Workbook

Sheet Лист1
A1: № | B1: наименование | C1: остаток | D1: приход | E1: перемещение | F1: расход | G1: расход | H1: расход | I1: остаток
A2: 1 | B2: ='[1]28.01'!B2 -> Немирофф 1л | C2: =[2]Лист11!I2 -> 2.85 | I2: =C2+D2-E2-F2-G2-H2 -> 2.85
A3: 2 | B3: ='[1]28.01'!B3 -> Немирофф 0,7 | C3: =[2]Лист11!I3 -> 6 | I3: =C3+D3-E3-F3-G3-H3 -> 6
A4: 3 | B4: ='[1]28.01'!B4 -> Немирофф 0,5 | C4: =[2]Лист11!I4 -> 6 | I4: =C4+D4-E4-F4-G4-H4 -> 6
A5: 4 | B5: Романов 0,5 | C5: =[2]Лист11!I5 -> 0 | I5: =C5+D5-E5-F5-G5-H5 -> 0
A6: 5 | B6: ='[1]28.01'!B6 -> Зерно 0,7 | C6: =[2]Лист11!I6 -> 3.2 | I6: =C6+D6-E6-F6-G6-H6 -> 3.2
A7: 6 | B7: Годунов 0,5 | C7: =[2]Лист11!I7 -> 7.3 | I7: =C7+D7-E7-F7-G7-H7 -> 7.3
A8: 7 | B8: ='[1]28.01'!B8 -> Хортица 1 л | C8: =[2]Лист11!I8 -> 3.4 | I8: =C8+D8-E8-F8-G8-H8 -> 3.4
A9: 8 | B9: ='[1]28.01'!B9 -> Хортица 0,7 | C9: =[2]Лист11!I9 -> 7 | I9: =C9+D9-E9-F9-G9-H9 -> 7
A10: 9 | B10: ='[1]28.01'!B10 -> Хортица 0,5 | C10: =[2]Лист11!I10 -> 9 | I10: =C10+D10-E10-F10-G10-H10 -> 9
A11: 10 | B11: ='[1]28.01'!B11 -> Зеленая марка 1л | C11: =[2]Лист11!I11 -> 1.3 | I11: =C11+D11-E11-F11-G11-H11 -> 1.3
A12: 11 | B12: ='[1]28.01'!B12 -> Зеленая марка 0,7 | C12: =[2]Лист11!I12 -> 5 | I12: =C12+D12-E12-F12-G12-H12 -> 5
A13: 12 | B13: ='[1]28.01'!B13 -> Зеленая марка 0,5 | C13: =[2]Лист11!I13 -> 3 | I13: =C13+D13-E13-F13-G13-H13 -> 3
A14: 13 | B14: ='[1]28.01'!B14 -> Хаома 1л | C14: =[2]Лист11!I14 -> 1.85 | I14: =C14+D14-E14-F14-G14-H14 -> 1.85
A15: 14 | B15: ='[1]28.01'!B15 -> Хаома 0,7 | C15: =[2]Лист11!I15 -> 4 | I15: =C15+D15-E15-F15-G15-H15 -> 4
A16: 15 | B16: ='[1]28.01'!B16 -> Хаома 0,5 | C16: =[2]Лист11!I16 -> 3 | I16: =C16+D16-E16-F16-G16-H16 -> 3
A17: 16 | B17: Талка 0,7 | C17: =[2]Лист11!I17 -> 2 | I17: =C17+D17-E17-F17-G17-H17 -> 2
A18: 17 | B18: Талка 0,5 | C18: =[2]Лист11!I18 -> 0 | I18: =C18+D18-E18-F18-G18-H18 -> 0
A19: 18 | B19: ='[1]28.01'!B17 -> JACK DANIELS 1л | C19: =[2]Лист11!I19 -> 1.4 | I19: =C19+D19-E19-F19-G19-H19 -> 1.4
A20: 19 | B20: ='[1]28.01'!B18 -> JACK DANIELS 0,7 | C20: =[2]Лист11!I20 -> 2 | I20: =C20+D20-E20-F20-G20-H20 -> 2
A21: 20 | B21: ='[1]28.01'!B19 -> JACK DANIELS 0,5 | C21: =[2]Лист11!I21 -> 1 | I21: =C21+D21-E21-F21-G21-H21 -> 1
A22: 21 | B22: ='[1]28.01'!B20 -> JAMESON 1л | C22: =[2]Лист11!I22 -> 0.8 | I22: =C22+D22-E22-F22-G22-H22 -> 0.8
A23: 22 | B23: ='[1]28.01'!B21 -> JAMESON 0,7 | C23: =[2]Лист11!I23 -> 2 | I23: =C23+D23-E23-F23-G23-H23 -> 2
A24: 23 | B24: ='[1]28.01'!B22 -> JAMESON 0,5 | C24: =[2]Лист11!I24 -> 2 | I24: =C24+D24-E24-F24-G24-H24 -> 2
A25: 24 | B25: ='[1]28.01'!B23 -> Скотч 0,7 | C25: =[2]Лист11!I25 -> 2.4 | I25: =C25+D25-E25-F25-G25-H25 -> 2.4
A26: 25 | B26: ='[1]28.01'!B24 -> Скотч 0,5 | C26: =[2]Лист11!I26 -> 3 | I26: =C26+D26-E26-F26-G26-H26 -> 3
A27: 26 | B27: ='[1]28.01'!B25 -> Ром 1л | C27: =[2]Лист11!I27 -> 1.25 | I27: =C27+D27-E27-F27-G27-H27 -> 1.25
A28: 27 | B28: Ром 0,7 | C28: =[2]Лист11!I28 -> 2 | I28: =C28+D28-E28-F28-G28-H28 -> 2
A29: 28 | B29: Ром 0,5 | C29: =[2]Лист11!I29 -> 2 | I29: =C29+D29-E29-F29-G29-H29 -> 2
A30: 29 | B30: Коньяк 0,7 | C30: =[2]Лист11!I30 -> 2.7 | I30: =C30+D30-E30-F30-G30-H30 -> 2.7
A31: 30 | B31: Коньяк 0,5 | C31: =[2]Лист11!I31 -> 2 | I31: =C31+D31-E31-F31-G31-H31 -> 2
A32: 31 | B32: ='[1]28.01'!B30 -> Алазанская долина | C32: =[2]Лист11!I32 -> 8 | I32: =C32+D32-E32-F32-G32-H32 -> 8
A33: 32 | B33: ='[1]28.01'!B31 -> Бахус | C33: =[2]Лист11!I33 -> 3 | I33: =C33+D33-E33-F33-G33-H33 -> 3
A34: 33 | B34: ='[1]28.01'!B32 -> Изуми | C34: =[2]Лист11!I34 -> 2 | I34: =C34+D34-E34-F34-G34-H34 -> 2
A35: 34 | B35: ='[1]28.01'!B33 -> Киндзмараули | C35: =[2]Лист11!I35 -> 0 | I35: =C35+D35-E35-F35-G35-H35 -> 0
A36: 35 | B36: ='[1]28.01'!B34 -> Ркацетели | C36: =[2]Лист11!I36 -> 3 | I36: =C36+D36-E36-F36-G36-H36 -> 3
A37: 36 | B37: ='[1]28.01'!B35 -> Шампанское | C37: =[2]Лист11!I37 -> 0 | I37: =C37+D37-E37-F37-G37-H37 -> 0
A38: 37 | B38: ='[1]28.01'!B36 -> Мартини 1л | C38: =[2]Лист11!I38 -> 0.85 | I38: =C38+D38-E38-F38-G38-H38 -> 0.85
A39: 38 | B39: Холстен | C39: =[2]Лист11!I39 -> 11 | I39: =C39+D39-E39-F39-G39-H39 -> 11
A40: 39 | B40: ='[1]28.01'!B38 -> Балтика 0 | C40: =[2]Лист11!I40 -> 14 | I40: =C40+D40-E40-F40-G40-H40 -> 14
...
